Workbook

Sheet 00_文档信息
A1: 单踏板控制系统 HARA 主表
A2: 状态：Draft。本工作簿作为单踏板控制系统概念阶段HARA初始基线；所有评级均需由授权功能安全团队评审批准。
A4: 字段 | B4: 内容 | D4: HARA 状态摘要
A5: 文档名称 | B5: 单踏板控制系统危害分析与风险评估（HARA） | D5: 有效危险事件 | E5: =COUNTA('04_危害事件'!$A$4:$A$48) -> 45
A6: 文档标识 | B6: OPC-HARA-001 | D6: ASIL C | E6: =COUNTIF('04_危害事件'!$N$4:$N$48,"C") -> 1
A7: 版本 | B7: 1.0 | D7: ASIL B | E7: =COUNTIF('04_危害事件'!$N$4:$N$48,"B") -> 5
A8: 状态 | B8: Draft（待评审批准） | D8: ASIL A | E8: =COUNTIF('04_危害事件'!$N$4:$N$48,"A") -> 13
A9: 项目 | B9: One Pedal Controller | D9: QM | E9: =COUNTIF('04_危害事件'!$N$4:$N$48,"QM") -> 26
A10: Item Definition | B10: OPC-ITEM-DEF-001（本项目受控配套工作产品） | D10: Open问题 | E10: =COUNTIF('08_开放问题'!$G$4:$G$18,"Open") -> 8
A11: 标准依据 | B11: ISO 26262-3:2018；ASIL矩阵复核参考 SAE J2980 与 NHTSA 公开研究
A12: 编制日期 | B12: 2026-08-06 | D12: 审批记录
A13: 编制/所有者 | B13: Nan | D13: 角色 | E13: 姓名 | F13: 部门 | G13: 结论 | H13: 日期
D14: 编制 | E14: Nan | F14: Nan | G14: Draft | H14: Nan
A15: 使用说明 | B15: 黄色单元格为需人工维护/确认的输入；绿色单元格为公式计算；所有TBD和Open问题必须在基线发布前关闭或批准偏差。 | D15: 功能安全经理 | E15: Yi | F15: Yi | G15: 待评审 | H15: Yi
A16: 工作产品关系 | B16: Item边界由OPC-ITEM-DEF-001定义；本工作簿独立完成HARA；安全目标批准后进入FSC和需求管理工具。 | D16: 项目经理 | E16: Yi | F16: Yi | G16: 待批准 | H16: Yi
A17: 限制 | B17: 本文件为通用企业级模板，未获得用户所在公司的专用模板、审批流和裁剪规则，不能单独作为合规认证声明。 | D17: 独立确认评审 | E17: Yi | F17: Yi | G17: 待确认 | H17: Yi
A18: ISO参考 | B18: https://www.iso.org/standard/68385.html
A19: SAE参考 | B19: https://saemobilus.sae.org/standards/j2980_202310-considerations-iso-26262-asil-hazard-classification

Sheet 01_Item范围
A1: Item 范围与关键约束
A2: 本页给出HARA采用的Item边界、外部接口、假设与关键约束，并与OPC-ITEM-DEF-001共同构成概念阶段输入。
A3: ID | B3: 类别 | C3: 名称 | D3: 定义/责任 | E3: 边界内 | F3: 安全相关 | G3: 来源 | H3: 状态
A4: ITM-001 | B4: Item | C4: 单踏板控制系统 | D4: 根据踏板、制动、挡位、车速及有效性计算电机侧扭矩请求并管理运行状态 | E4: 是 | F4: 是 | G4: Item Definition §2 | H4: Draft
A5: EXT-001 | B5: 外部系统 | C5: 液压制动系统 | D5: 独立执行驾驶员机械制动；Item仅接收制动踏板状态 | E5: 否 | F5: 是 | G5: §3.3 / ASM-001 | H5: Draft
A6: EXT-002 | B6: 外部系统 | C6: 电机ECU | D6: 执行有效扭矩请求并拒绝无效/越界请求 | E6: 否 | F6: 是 | G6: §3.3 / ASM-002 | H6: Draft
A7: EXT-003 | B7: 外部系统 | C7: 车速来源ECU | D7: 提供有符号车速及有效性 | E7: 否 | F7: 是 | G7: §3.3 / ASM-003 | H7: Draft
A8: EXT-004 | B8: 外部系统 | C8: 挡位选择器 | D8: 提供P/R/N/D/B请求及有效性 | E8: 否 | F8: 是 | G8: §3.3 / ASM-004 | H8: Draft
A9: EXT-005 | B9: 外部系统 | C9: 三路踏板传感器 | D9: 提供三路归一化踏板位置及电气诊断 | E9: 否 | F9: 是 | G9: §3.3 / ASM-005 | H9: Draft
A10: EXT-006 | B10: 外部系统 | C10: CAN通信服务 | D10: 提供信号新鲜度、超时和通信诊断 | E10: 否 | F10: 是 | G10: §3.3 / ASM-006 | H10: Draft
A11: EXT-007 | B11: 外部系统 | C11: HMI/仪表 | D11: 显示实际挡位、运行状态及故障告警 | E11: 否 | F11: 是 | G11: §3.3 / ASM-007 | H11: Draft
A12: ENV-001 | B12: 验证环境 | C12: Vehicle Plant/Driver/Harness | D12: 仅用于MIL验证，不属于量产Item或安全机制 | E12: 否 | F12: 否 | G12: §3.4 / §12 | H12: Confirmed
A13: CON-001 | B13: 约束 | C13: 控制周期 | D13: 10 ms | E13: 是 | F13: 是 | G13: §4.1 | H13: Draft
A14: CON-002 | B14: 约束 | C14: 电机侧扭矩范围 | D14: −80 Nm～+80 Nm；R挡最小−40 Nm；B挡再生最小−80 Nm | E14: 是 | F14: 是 | G14: §4.1 | H14: Draft
... A17: CON-005 | B17: 约束 | C17: 制动优先 | D17: 有效制动踏板被踩下时不得输出驱动扭矩 | E17: 是 | F17: 是 | G17: §9 | H17: Draft

Sheet 02_功能与异常
A1: Item 功能与功能异常
A2: 功能异常采用Guideword、接口分析和时序分析识别丢失、过多、过少、非预期、错误方向及过早/过晚等异常。
A3: 功能ID | B3: Item功能 | C3: 输入/触发 | D3: 正常输出/行为 | E3: 来源
A4: FUN-001 | B4: 踏板输入获取与可信度判断 | C4: 三路踏板位置及有效性 | D4: 输出可信踏板位置和故障状态 | E4: Item §3.2
A5: FUN-002 | B5: 挡位管理与换挡约束 | C5: 请求挡位、制动状态、车速 | D5: 输出实际挡位或拒绝状态 | E5: Item §4.8
A6: FUN-003 | B6: D挡驱动扭矩计算 | C6: 可信踏板、D挡 | D6: 0～+80 Nm驱动扭矩 | E6: Item §4.6
A7: FUN-004 | B7: R挡倒车扭矩计算 | C7: 可信踏板、R挡 | D7: 0～−40 Nm倒车扭矩 | E7: Item §4.4
A8: FUN-005 | B8: B挡驱动/再生扭矩计算 | C8: 可信踏板、B挡、车速 | D8: −80～+80 Nm扭矩 | E8: Item §4.7
A9: FUN-006 | B9: 零速停车保持 | C9: B挡、接近零速、坡度 | D9: 受控保持0 km/h，不越过零速 | E9: Item §4.7
A10: FUN-007 | B10: 制动踏板优先处理 | C10: 有效制动踏板状态 | D10: 取消驱动扭矩请求 | E10: Item §4.1
A11: FUN-008 | B11: 最终扭矩仲裁与限幅 | C11: 模式扭矩、可用扭矩、故障状态 | D11: 方向/幅值/变化率受限扭矩 | E11: Item §3.2
A12: FUN-009 | B12: 故障与运行状态管理 | C12: 输入诊断、内部诊断、复位 | D12: Normal/Degraded/Safe/Recovery | E12: Item §5
A13: FUN-010 | B13: 状态与告警输出 | C13: 实际挡位、故障、运行状态 | D13: 诊断与HMI告警请求 | E13: Item §6.2
A16: 功能异常清单
A17: 异常ID | B17: 识别方法 | C17: 关联功能 | D17: Guideword | E17: 功能异常描述 | F17: 潜在危害 | G17: 检测/外部措施假设 | H17: 是否进入HARA | I17: 状态 | J17: 备注
A18: MF-001 | B18: Guideword | C18: FUN-003/FUN-005/FUN-008 | D18: 过大/非预期 | E18: 产生过大的正向驱动扭矩或无请求时产生正扭矩 | F18: H1 非预期加速 | G18: 独立制动、踏板诊断、扭矩限幅 | H18: 是 | I18: Draft | J18: 方向需在危险事件中明确
A19: MF-002 | B19: Guideword | C19: FUN-005/FUN-008 | D19: 过大/非预期 | E19: 产生过大的负向再生扭矩或无请求时产生负扭矩 | F19: H2 非预期减速 | G19: 独立制动不能消除非预期再生，需快速切断 | H19: 是 | I19: Draft | J19: 正负扭矩方向分别分析
A20: MF-003 | B20: Guideword | C20: FUN-003/FUN-008 | D20: 过小/丢失 | E20: 正向驱动扭矩低于驾驶员合理请求 | F20: H3 加速不足 | G20: 驾驶员可减速并退出交通流 | H20: 是 | I20: Draft | J20: 需定义最小性能边界
A21: MF-004 | B21: Guideword | C21: FUN-005/FUN-008 | D21: 过小/丢失 | E21: 再生制动扭矩低于合理请求 | F21: H4 减速不足 | G21: 驾驶员可使用独立液压制动 | H21: 是 | I21: Draft | J21: 外部措施需DFA确认
A22: MF-005 | B22: Guideword | C22: FUN-001 | D22: 偏高 | E22: 可信踏板位置被计算得过高 | F22: H1 非预期加速 | G22: 三路表决、范围/一致性诊断 | H22: 是 | I22: Draft
A23: MF-006 | B23: Guideword | C23: FUN-001 | D23: 偏低 | E23: 可信踏板位置被计算得过低 | F23: H3 加速不足/H4减速不足 | G23: 三路表决、范围/一致性诊断 | H23: 是 | I23: Draft | J23: B挡踏板偏低可增加制动
A24: MF-007 | B24: 接口分析 | C24: FUN-002/FUN-005/FUN-006 | D24: 错误/丢失 | E24: 未检测车速无效、方向错误或零速判断错误 | F24: H5 错误方向运动/H1/H2 | G24: 车速有效性与方向合理性诊断 | H24: 是 | I24: Draft
A25: MF-008 | B25: 时序分析 | C25: FUN-002 | D25: 错误时序 | E25: 在不满足车速/制动条件时接受危险方向挡位 | F25: H5 错误方向运动 | G25: 换挡互锁 | H25: 是 | I25: Draft
A26: MF-009 | B26: 接口分析 | C26: FUN-007 | D26: 丢失 | E26: 制动踏板踩下时未取消驱动扭矩 | F26: H1 非预期加速 | G26: 制动信号有效性和独立液压制动 | H26: 是 | I26: Draft
A27: MF-010 | B27: 时序分析 | C27: FUN-009 | D27: 过晚 | E27: 故障检测或安全反应超过FTTI | F27: H1/H2/H5 | G27: 任务监控、故障管理 | H27: 是 | I27: Draft | J27: 需FTTI预算
A28: MF-011 | B28: Guideword | C28: FUN-006 | D28: 非预期/丢失 | E28: 停车保持不足或产生反向运动 | F28: H5 错误方向运动 | G28: 独立制动/驻车系统 | H28: 是 | I28: Draft | J28: 需坡道场景
A29: MF-012 | B29: 时序分析 | C29: FUN-009 | D29: 非预期 | E29: 初始化、复位或恢复期间产生非零扭矩 | F29: H1/H2/H5 | G29: 初始化零扭矩和输出无效状态 | H29: 是 | I29: Draft | J29: 需启动/恢复场景

Sheet 03_运行场景
A1: 车辆运行场景
A2: HARA基线覆盖高速、拥堵、倒车、静止起步及湿滑路面等设计运行场景；扩展场景作为完整性评审输入，在批准后纳入基线。
A3: 场景ID | B3: 道路/地点 | C3: 车速状态 | D3: 运动方向 | E3: 交通/人员 | F3: 路面 | G3: 坡度 | H3: 驾驶动作 | I3: 挡位 | J3: 适用性 | K3: E建议 | L3: 评审说明
A4: OS1 | B4: 高速公路 | C4: 高速 | D4: 前进 | E4: 一般交通 | F4: 干燥 | G4: 平路 | H4: 巡航/超车 | I4: D/B | J4: 适用 | K4: E1 | L4: 基线场景
A5: OS2 | B5: 高速公路 | C5: 低速 | D5: 前进 | E5: 拥堵 | F5: 干燥 | G5: 平路 | H5: 跟车 | I5: D/B | J5: 适用 | K5: E1 | L5: 基线场景
A6: OS3 | B6: 高速公路 | C6: 倒车 | D6: 倒车 | E6: 一般交通 | F6: 干燥 | G6: 平路 | H6: 倒车 | I6: R | J6: 排除 | K6: E0 | L6: 不合理组合
A7: OS4 | B7: 高速公路 | C7: 静止 | D7: 静止 | E7: 一般交通 | F7: 干燥 | G7: 平路 | H7: 停车 | I7: P/N/D/B | J7: 排除 | K7: E0 | L7: 由低速拥堵及静止起步场景覆盖
A8: OS5 | B8: 拥堵道路 | C8: 高速 | D8: 前进 | E8: 密集交通/行人 | F8: 干燥 | G8: 平路 | H8: 行驶 | I8: D/B | J8: 排除 | K8: E0 | L8: 速度与场景定义矛盾
A9: OS6 | B9: 拥堵道路 | C9: 低速 | D9: 前进 | E9: 密集交通/行人 | F9: 干燥 | G9: 平路 | H9: 跟车/起停 | I9: D/B | J9: 适用 | K9: E3 | L9: 基线场景
A10: OS7 | B10: 拥堵道路 | C10: 低速 | D10: 倒车 | E10: 车辆/行人 | F10: 干燥 | G10: 平路 | H10: 倒车 | I10: R | J10: 适用 | K10: E2 | L10: 基线场景
A11: OS8 | B11: 拥堵道路 | C11: 静止 | D11: 静止 | E11: 车辆/行人 | F11: 干燥 | G11: 平路 | H11: 起步/停车 | I11: P/N/D/B | J11: 适用 | K11: E2 | L11: 基线场景
A12: OS9 | B12: 道路 | C12: 高速 | D12: 前进 | E12: 一般交通 | F12: 湿滑 | G12: 平路 | H12: 行驶 | I12: D/B | J12: 适用 | K12: E1 | L12: 基线场景
A13: OS10 | B13: 道路 | C13: 低速 | D13: 前进 | E13: 车辆/行人 | F13: 湿滑 | G13: 平路 | H13: 跟车/起停 | I13: D/B | J13: 适用 | K13: E2 | L13: 基线场景
A14: OS11 | B14: 道路 | C14: 低速 | D14: 倒车 | E14: 车辆/行人 | F14: 湿滑 | G14: 平路 | H14: 倒车 | I14: R | J14: 适用 | K14: E2 | L14: 基线场景
... A19: OS16 | B19: 任意道路 | C19: 接近零速 | D19: 换向风险 | E19: 车辆/行人 | F19: 任意 | G19: 任意 | H19: 危险方向换挡 | I19: P/R/N/D/B | J19: 待评估 | K19: TBD | L19: 换挡互锁扩展场景

Sheet 06_SEC准则
A1: S/E/C 评级准则与 ASIL 查表
A2: S/E/C由功能安全评审团队结合客观数据和专家判断确认。查表值依据公开的ISO 26262概念阶段复核资料；公司正式基线应采用受控标准副本。
A3: 严重度 | B3: 定义 | C3: 项目应用提示 | E3: 说明 | F3: S | G3: E | H3: C | I3: ASIL
A4: S0 | B4: 无伤害 | C4: 不形成安全相关危险事件 | E4: S1E1C1 | F4: S1 | G4: E1 | H4: C1 | I4: QM
A5: S1 | B5: 轻度和中度伤害 | C5: 低速轻微碰撞等 | E5: S1E1C2 | F5: S1 | G5: E1 | H5: C2 | I5: QM
A6: S2 | B6: 严重且危及生命，存活概率较高 | C6: 中等碰撞或存在严重伤害 | E6: S1E1C3 | F6: S1 | G6: E1 | H6: C3 | I6: QM
A7: S3 | B7: 危及生命且存活不确定，或致命伤害 | C7: 高速碰撞、行人严重伤害等 | E7: S1E2C1 | F7: S1 | G7: E2 | H7: C1 | I7: QM
E8: S1E2C2 | F8: S1 | G8: E2 | H8: C2 | I8: QM
E9: S1E2C3 | F9: S1 | G9: E2 | H9: C3 | I9: QM
A10: 暴露度 | B10: 定义 | C10: 项目应用提示 | E10: S1E3C1 | F10: S1 | G10: E3 | H10: C1 | I10: QM
A11: E0 | B11: 极不可能 | C11: 排除或不可合理预见的场景 | E11: S1E3C2 | F11: S1 | G11: E3 | H11: C2 | I11: QM
A12: E1 | B12: 很低概率 | C12: 罕见运行场景 | E12: S1E3C3 | F12: S1 | G12: E3 | H12: C3 | I12: A
A13: E2 | B13: 低概率 | C13: 偶发场景 | E13: S1E4C1 | F13: S1 | G13: E4 | H13: C1 | I13: QM
A14: E3 | B14: 中等概率 | C14: 经常遇到的场景 | E14: S1E4C2 | F14: S1 | G14: E4 | H14: C2 | I14: A
A15: E4 | B15: 高概率 | C15: 车辆运行中高度频繁 | E15: S1E4C3 | F15: S1 | G15: E4 | H15: C3 | I15: B
E16: S2E1C1 | F16: S2 | G16: E1 | H16: C1 | I16: QM
E17: S2E1C2 | F17: S2 | G17: E1 | H17: C2 | I17: QM
A18: 可控度 | B18: 定义 | C18: 项目应用提示 | E18: S2E1C3 | F18: S2 | G18: E1 | H18: C3 | I18: QM
A19: C0 | B19: 通常可控 | C19: 不形成安全相关危险事件 | E19: S2E2C1 | F19: S2 | G19: E2 | H19: C1 | I19: QM
A20: C1 | B20: 容易控制 | C20: 绝大多数驾驶员可及时避免伤害 | E20: S2E2C2 | F20: S2 | G20: E2 | H20: C2 | I20: QM
A21: C2 | B21: 通常可控 | C21: 多数驾驶员可控制，但需要及时反应 | E21: S2E2C3 | F21: S2 | G21: E2 | H21: C3 | I21: A
A22: C3 | B22: 难以控制或不可控 | C22: 驾驶员反应时间/措施不足 | E22: S2E3C1 | F22: S2 | G22: E3 | H22: C1 | I22: QM
E23: S2E3C2 | F23: S2 | G23: E3 | H23: C2 | I23: A
E24: S2E3C3 | F24: S2 | G24: E3 | H24: C3 | I24: B
E25: S2E4C1 | F25: S2 | G25: E4 | H25: C1 | I25: A
E26: S2E4C2 | F26: S2 | G26: E4 | H26: C2 | I26: B
E27: S2E4C3 | F27: S2 | G27: E4 | H27: C3 | I27: C
E28: S3E1C1 | F28: S3 | G28: E1 | H28: C1 | I28: QM
E29: S3E1C2 | F29: S3 | G29: E1 | H29: C2 | I29: QM
E30: S3E1C3 | F30: S3 | G30: E1 | H30: C3 | I30: A
E31: S3E2C1 | F31: S3 | G31: E2 | H31: C1 | I31: QM
E32: S3E2C2 | F32: S3 | G32: E2 | H32: C2 | I32: A
E33: S3E2C3 | F33: S3 | G33: E2 | H33: C3 | I33: B
E34: S3E3C1 | F34: S3 | G34: E3 | H34: C1 | I34: A
... E39: S3E4C3 | F39: S3 | G39: E4 | H39: C3 | I39: D
E42: 规则说明
E43: S0/E0/C0 | F43: 若任一参数为0，通常归为QM；需保留理由和评审记录。
E44: 危险级ASIL | F44: 同一危害跨运行场景时，采用经批准的最高ASIL作为相关安全目标ASIL。
E45: 来源 | F45: ISO 26262-3:2018；NHTSA公开报告表A-5；SAE J2980_202310。

Sheet 04_危害事件
A1: 危险事件与S/E/C评估
A2: 每一行代表“功能异常 + 车辆级危害 + 运行场景”。黄色列为人工判断；ASIL由受控查表公式计算。当前基线覆盖9个适用运行场景。
A3: 危险事件ID | B3: 状态 | C3: 功能ID | D3: 功能异常ID | E3: 危害ID | F3: 运行场景ID | G3: 危险事件描述 | H3: S | I3: S判断理由 | J3: E | K3: E判断理由 | L3: C | M3: C判断理由 | N3: 计算ASIL | O3: 安全目标ID | P3: 安全状态 | Q3: FTTI(ms) | R3: 依据/证据 | S3: ASIL分值 | T3: 评审结论 | U3: 评审人 | V3: 备注
A4: HE-001 | B4: Draft | C4: FUN-003/FUN-005/FUN-008 | D4: MF-001/MF-005/MF-009/MF-012 | E4: H1 | F4: OS1 | G4: 车辆非预期加速，发生于OS1运行场景 | H4: S3 | I4: 高速公路发生车辆非预期加速可能导致高速碰撞、行人碰撞或致命伤害。 | J4: E1 | K4: 依据本项目运行场景定义及概念阶段专家判断，OS1暴露度暂定为很低概率；需由目标市场、车队或场景统计数据复核。 | L4: C2 | M4: 多数驾驶员可通过制动、转向或调整踏板控制后果，但需要及时反应。 | N4: =VLOOKUP(H4&J4&L4,'06_SEC准则'!$E$4:$I$39,5,FALSE) -> QM | O4: SG-001 | P4: 扭矩请求置0；请求无效；驾驶员声光告警 | Q4: 100 | R4: OPC-ITEM-DEF-001；运行场景分析；概念阶段专家判断待评审 | S4: =IF(N4="QM",0,IF(N4="A",1,IF(N4="B",2,IF(N4="C",3,IF(N4="D",4,""))))) -> 0 | T4: 待FuSa评审 | U4: TBD
A5: HE-002 | B5: Draft | C5: FUN-003/FUN-005/FUN-008 | D5: MF-001/MF-005/MF-009/MF-012 | E5: H1 | F5: OS2 | G5: 车辆非预期加速，发生于OS2运行场景 | H5: S3 | I5: 高速公路发生车辆非预期加速可能导致高速碰撞、行人碰撞或致命伤害。 | J5: E1 | K5: 依据本项目运行场景定义及概念阶段专家判断，OS2暴露度暂定为很低概率；需由目标市场、车队或场景统计数据复核。 | L5: C2 | M5: 多数驾驶员可通过制动、转向或调整踏板控制后果，但需要及时反应。 | N5: =VLOOKUP(H5&J5&L5,'06_SEC准则'!$E$4:$I$39,5,FALSE) -> QM | O5: SG-001 | P5: 扭矩请求置0；请求无效；驾驶员声光告警 | Q5: 100 | R5: OPC-ITEM-DEF-001；运行场景分析；概念阶段专家判断待评审 | S5: =IF(N5="QM",0,IF(N5="A",1,IF(N5="B",2,IF(N5="C",3,IF(N5="D",4,""))))) -> 0 | T5: 待FuSa评审 | U5: TBD
A6: HE-003 | B6: Draft | C6: FUN-003/FUN-005/FUN-008 | D6: MF-001/MF-005/MF-009/MF-012 | E6: H1 | F6: OS6 | G6: 车辆非预期加速，发生于OS6运行场景 | H6: S3 | I6: 拥堵道路发生车辆非预期加速可能导致高速碰撞、行人碰撞或致命伤害。 | J6: E3 | K6: 依据本项目运行场景定义及概念阶段专家判断，OS6暴露度暂定为中等概率；需由目标市场、车队或场景统计数据复核。 | L6: C3 | M6: 车辆非预期加速发生后驾驶员可用反应时间或外部措施有限，难以控制或不可控。 | N6: =VLOOKUP(H6&J6&L6,'06_SEC准则'!$E$4:$I$39,5,FALSE) -> C | O6: SG-001 | P6: 扭矩请求置0；请求无效；驾驶员声光告警 | Q6: 100 | R6: OPC-ITEM-DEF-001；运行场景分析；概念阶段专家判断待评审 | S6: =IF(N6="QM",0,IF(N6="A",1,IF(N6="B",2,IF(N6="C",3,IF(N6="D",4,""))))) -> 3 | T6: 待FuSa评审 | U6: TBD
A7: HE-004 | B7: Draft | C7: FUN-003/FUN-005/FUN-008 | D7: MF-001/MF-005/MF-009/MF-012 | E7: H1 | F7: OS7 | G7: 车辆非预期加速，发生于OS7运行场景 | H7: S2 | I7: 拥堵道路发生车辆非预期加速可能导致严重碰撞或严重伤害，但存活概率较高。 | J7: E2 | K7: 依据本项目运行场景定义及概念阶段专家判断，OS7暴露度暂定为低概率；需由目标市场、车队或场景统计数据复核。 | L7: C2 | M7: 多数驾驶员可通过制动、转向或调整踏板控制后果，但需要及时反应。 | N7: =VLOOKUP(H7&J7&L7,'06_SEC准则'!$E$4:$I$39,5,FALSE) -> QM | O7: SG-001 | P7: 扭矩请求置0；请求无效；驾驶员声光告警 | Q7: 100 | R7: OPC-ITEM-DEF-001；运行场景分析；概念阶段专家判断待评审 | S7: =IF(N7="QM",0,IF(N7="A",1,IF(N7="B",2,IF(N7="C",3,IF(N7="D",4,""))))) -> 0 | T7: 待FuSa评审 | U7: TBD
A8: HE-005 | B8: Draft | C8: FUN-003/FUN-005/FUN-008 | D8: MF-001/MF-005/MF-009/MF-012 | E8: H1 | F8: OS8 | G8: 车辆非预期加速，发生于OS8运行场景 | H8: S2 | I8: 拥堵道路发生车辆非预期加速可能导致严重碰撞或严重伤害，但存活概率较高。 | J8: E2 | K8: 依据本项目运行场景定义及概念阶段专家判断，OS8暴露度暂定为低概率；需由目标市场、车队或场景统计数据复核。 | L8: C2 | M8: 多数驾驶员可通过制动、转向或调整踏板控制后果，但需要及时反应。 | N8: =VLOOKUP(H8&J8&L8,'06_SEC准则'!$E$4:$I$39,5,FALSE) -> QM | O8: SG-001 | P8: 扭矩请求置0；请求无效；驾驶员声光告警 | Q8: 100 | R8: OPC-ITEM-DEF-001；运行场景分析；概念阶段专家判断待评审 | S8: =IF(N8="QM",0,IF(N8="A",1,IF(N8="B",2,IF(N8="C",3,IF(N8="D",4,""))))) -> 0 | T8: 待FuSa评审 | U8: TBD
A9: HE-006 | B9: Draft | C9: FUN-003/FUN-005/FUN-008 | D9: MF-001/MF-005/MF-009/MF-012 | E9: H1 | F9: OS9 | G9: 车辆非预期加速，发生于OS9运行场景 | H9: S3 | I9: 湿滑道路发生车辆非预期加速可能导致高速碰撞、行人碰撞或致命伤害。 | J9: E1 | K9: 依据本项目运行场景定义及概念阶段专家判断，OS9暴露度暂定为很低概率；需由目标市场、车队或场景统计数据复核。 | L9: C2 | M9: 多数驾驶员可通过制动、转向或调整踏板控制后果，但需要及时反应。 | N9: =VLOOKUP(H9&J9&L9,'06_SEC准则'!$E$4:$I$39,5,FALSE) -> QM | O9: SG-001 | P9: 扭矩请求置0；请求无效；驾驶员声光告警 | Q9: 100 | R9: OPC-ITEM-DEF-001；运行场景分析；概念阶段专家判断待评审 | S9: =IF(N9="QM",0,IF(N9="A",1,IF(N9="B",2,IF(N9="C",3,IF(N9="D",4,""))))) -> 0 | T9: 待FuSa评审 | U9: TBD
A10: HE-007 | B10: Draft | C10: FUN-003/FUN-005/FUN-008 | D10: MF-001/MF-005/MF-009/MF-012 | E10: H1 | F10: OS10 | G10: 车辆非预期加速，发生于OS10运行场景 | H10: S3 | I10: 湿滑道路发生车辆非预期加速可能导致高速碰撞、行人碰撞或致命伤害。 | J10: E2 | K10: 依据本项目运行场景定义及概念阶段专家判断，OS10暴露度暂定为低概率；需由目标市场、车队或场景统计数据复核。 | L10: C2 | M10: 多数驾驶员可通过制动、转向或调整踏板控制后果，但需要及时反应。 | N10: =VLOOKUP(H10&J10&L10,'06_SEC准则'!$E$4:$I$39,5,FALSE) -> A | O10: SG-001 | P10: 扭矩请求置0；请求无效；驾驶员声光告警 | Q10: 100 | R10: OPC-ITEM-DEF-001；运行场景分析；概念阶段专家判断待评审 | S10: =IF(N10="QM",0,IF(N10="A",1,IF(N10="B",2,IF(N10="C",3,IF(N10="D",4,""))))) -> 1 | T10: 待FuSa评审 | U10: TBD
A11: HE-008 | B11: Draft | C11: FUN-003/FUN-005/FUN-008 | D11: MF-001/MF-005/MF-009/MF-012 | E11: H1 | F11: OS11 | G11: 车辆非预期加速，发生于OS11运行场景 | H11: S2 | I11: 湿滑道路发生车辆非预期加速可能导致严重碰撞或严重伤害，但存活概率较高。 | J11: E2 | K11: 依据本项目运行场景定义及概念阶段专家判断，OS11暴露度暂定为低概率；需由目标市场、车队或场景统计数据复核。 | L11: C2 | M11: 多数驾驶员可通过制动、转向或调整踏板控制后果，但需要及时反应。 | N11: =VLOOKUP(H11&J11&L11,'06_SEC准则'!$E$4:$I$39,5,FALSE) -> QM | O11: SG-001 | P11: 扭矩请求置0；请求无效；驾驶员声光告警 | Q11: 100 | R11: OPC-ITEM-DEF-001；运行场景分析；概念阶段专家判断待评审 | S11: =IF(N11="QM",0,IF(N11="A",1,IF(N11="B",2,IF(N11="C",3,IF(N11="D",4,""))))) -> 0 | T11: 待FuSa评审 | U11: TBD
A12: HE-009 | B12: Draft | C12: FUN-003/FUN-005/FUN-008 | D12: MF-001/MF-005/MF-009/MF-012 | E12: H1 | F12: OS12 | G12: 车辆非预期加速，发生于OS12运行场景 | H12: S2 | I12: 湿滑道路发生车辆非预期加速可能导致严重碰撞或严重伤害，但存活概率较高。 | J12: E2 | K12: 依据本项目运行场景定义及概念阶段专家判断，OS12暴露度暂定为低概率；需由目标市场、车队或场景统计数据复核。 | L12: C2 | M12: 多数驾驶员可通过制动、转向或调整踏板控制后果，但需要及时反应。 | N12: =VLOOKUP(H12&J12&L12,'06_SEC准则'!$E$4:$I$39,5,FALSE) -> QM | O12: SG-001 | P12: 扭矩请求置0；请求无效；驾驶员声光告警 | Q12: 100 | R12: OPC-ITEM-DEF-001；运行场景分析；概念阶段专家判断待评审 | S12: =IF(N12="QM",0,IF(N12="A",1,IF(N12="B",2,IF(N12="C",3,IF(N12="D",4,""))))) -> 0 | T12: 待FuSa评审 | U12: TBD
A13: HE-010 | B13: Draft | C13: FUN-005/FUN-008 | D13: MF-002/MF-006/MF-012 | E13: H2 | F13: OS1 | G13: 车辆非预期减速，发生于OS1运行场景 | H13: S2 | I13: 高速公路发生车辆非预期减速可能导致严重碰撞或严重伤害，但存活概率较高。 | J13: E3 | K13: 依据本项目运行场景定义及概念阶段专家判断，OS1暴露度暂定为中等概率；需由目标市场、车队或场景统计数据复核。 | L13: C2 | M13: 多数驾驶员可通过制动、转向或调整踏板控制后果，但需要及时反应。 | N13: =VLOOKUP(H13&J13&L13,'06_SEC准则'!$E$4:$I$39,5,FALSE) -> A | O13: SG-002 | P13: 扭矩请求置0；请求无效；驾驶员声光告警 | Q13: 500 | R13: OPC-ITEM-DEF-001；运行场景分析；概念阶段专家判断待评审 | S13: =IF(N13="QM",0,IF(N13="A",1,IF(N13="B",2,IF(N13="C",3,IF(N13="D",4,""))))) -> 1 | T13: 待FuSa评审 | U13: TBD
A14: HE-011 | B14: Draft | C14: FUN-005/FUN-008 | D14: MF-002/MF-006/MF-012 | E14: H2 | F14: OS2 | G14: 车辆非预期减速，发生于OS2运行场景 | H14: S2 | I14: 高速公路发生车辆非预期减速可能导致严重碰撞或严重伤害，但存活概率较高。 | J14: E2 | K14: 依据本项目运行场景定义及概念阶段专家判断，OS2暴露度暂定为低概率；需由目标市场、车队或场景统计数据复核。 | L14: C2 | M14: 多数驾驶员可通过制动、转向或调整踏板控制后果，但需要及时反应。 | N14: =VLOOKUP(H14&J14&L14,'06_SEC准则'!$E$4:$I$39,5,FALSE) -> QM | O14: SG-002 | P14: 扭矩请求置0；请求无效；驾驶员声光告警 | Q14: 500 | R14: OPC-ITEM-DEF-001；运行场景分析；概念阶段专家判断待评审 | S14: =IF(N14="QM",0,IF(N14="A",1,IF(N14="B",2,IF(N14="C",3,IF(N14="D",4,""))))) -> 0 | T14: 待FuSa评审 | U14: TBD
A15: HE-012 | B15: Draft | C15: FUN-005/FUN-008 | D15: MF-002/MF-006/MF-012 | E15: H2 | F15: OS6 | G15: 车辆非预期减速，发生于OS6运行场景 | H15: S2 | I15: 拥堵道路发生车辆非预期减速可能导致严重碰撞或严重伤害，但存活概率较高。 | J15: E3 | K15: 依据本项目运行场景定义及概念阶段专家判断，OS6暴露度暂定为中等概率；需由目标市场、车队或场景统计数据复核。 | L15: C1 | M15: 驾驶员可通过独立制动或停止操作较容易地控制该情况。 | N15: =VLOOKUP(H15&J15&L15,'06_SEC准则'!$E$4:$I$39,5,FALSE) -> QM | O15: SG-002 | P15: 扭矩请求置0；请求无效；驾驶员声光告警 | Q15: 500 | R15: OPC-ITEM-DEF-001；运行场景分析；概念阶段专家判断待评审 | S15: =IF(N15="QM",0,IF(N15="A",1,IF(N15="B",2,IF(N15="C",3,IF(N15="D",4,""))))) -> 0 | T15: 待FuSa评审 | U15: TBD
A16: HE-013 | B16: Draft | C16: FUN-005/FUN-008 | D16: MF-002/MF-006/MF-012 | E16: H2 | F16: OS7 | G16: 车辆非预期减速，发生于OS7运行场景 | H16: S1 | I16: 拥堵道路低速/静止相关事件预期主要造成轻度至中度伤害。 | J16: E3 | K16: 依据本项目运行场景定义及概念阶段专家判断，OS7暴露度暂定为中等概率；需由目标市场、车队或场景统计数据复核。 | L16: C1 | M16: 驾驶员可通过独立制动或停止操作较容易地控制该情况。 | N16: =VLOOKUP(H16&J16&L16,'06_SEC准则'!$E$4:$I$39,5,FALSE) -> QM | O16: SG-002 | P16: 扭矩请求置0；请求无效；驾驶员声光告警 | Q16: 500 | R16: OPC-ITEM-DEF-001；运行场景分析；概念阶段专家判断待评审 | S16: =IF(N16="QM",0,IF(N16="A",1,IF(N16="B",2,IF(N16="C",3,IF(N16="D",4,""))))) -> 0 | T16: 待FuSa评审 | U16: TBD
A17: HE-014 | B17: Draft | C17: FUN-005/FUN-008 | D17: MF-002/MF-006/MF-012 | E17: H2 | F17: OS8 | G17: 车辆非预期减速，发生于OS8运行场景 | H17: S0 | I17: 该车辆状态下未识别可合理发生的伤害，待确认是否排除。 | J17: E0 | K17: 该场景与危害组合不适用或不可合理预见。 | L17: C0 | M17: 通常可控/不适用，需由评审确认。 | N17: ="QM" -> QM | O17: SG-002 | P17: 扭矩请求置0；请求无效；驾驶员声光告警 | Q17: 500 | R17: OPC-ITEM-DEF-001；运行场景分析；概念阶段专家判断待评审 | S17: =IF(N17="QM",0,IF(N17="A",1,IF(N17="B",2,IF(N17="C",3,IF(N17="D",4,""))))) -> 0 | T17: 待FuSa评审 | U17: TBD | V17: 该危害—场景组合暂按QM，排除理由需评审批准
A18: HE-015 | B18: Draft | C18: FUN-005/FUN-008 | D18: MF-002/MF-006/MF-012 | E18: H2 | F18: OS9 | G18: 车辆非预期减速，发生于OS9运行场景 | H18: S3 | I18: 湿滑道路发生车辆非预期减速可能导致高速碰撞、行人碰撞或致命伤害。 | J18: E1 | K18: 依据本项目运行场景定义及概念阶段专家判断，OS9暴露度暂定为很低概率；需由目标市场、车队或场景统计数据复核。 | L18: C3 | M18: 车辆非预期减速发生后驾驶员可用反应时间或外部措施有限，难以控制或不可控。 | N18: =VLOOKUP(H18&J18&L18,'06_SEC准则'!$E$4:$I$39,5,FALSE) -> A | O18: SG-002 | P18: 扭矩请求置0；请求无效；驾驶员声光告警 | Q18: 500 | R18: OPC-ITEM-DEF-001；运行场景分析；概念阶段专家判断待评审 | S18: =IF(N18="QM",0,IF(N18="A",1,IF(N18="B",2,IF(N18="C",3,IF(N18="D",4,""))))) -> 1 | T18: 待FuSa评审 | U18: TBD
A19: HE-016 | B19: Draft | C19: FUN-005/FUN-008 | D19: MF-002/MF-006/MF-012 | E19: H2 | F19: OS10 | G19: 车辆非预期减速，发生于OS10运行场景 | H19: S2 | I19: 湿滑道路发生车辆非预期减速可能导致严重碰撞或严重伤害，但存活概率较高。 | J19: E2 | K19: 依据本项目运行场景定义及概念阶段专家判断，OS10暴露度暂定为低概率；需由目标市场、车队或场景统计数据复核。 | L19: C2 | M19: 多数驾驶员可通过制动、转向或调整踏板控制后果，但需要及时反应。 | N19: =VLOOKUP(H19&J19&L19,'06_SEC准则'!$E$4:$I$39,5,FALSE) -> QM | O19: SG-002 | P19: 扭矩请求置0；请求无效；驾驶员声光告警 | Q19: 500 | R19: OPC-ITEM-DEF-001；运行场景分析；概念阶段专家判断待评审 | S19: =IF(N19="QM",0,IF(N19="A",1,IF(N19="B",2,IF(N19="C",3,IF(N19="D",4,""))))) -> 0 | T19: 待FuSa评审 | U19: TBD
A20: HE-017 | B20: Draft | C20: FUN-005/FUN-008 | D20: MF-002/MF-006/MF-012 | E20: H2 | F20: OS11 | G20: 车辆非预期减速，发生于OS11运行场景 | H20: S1 | I20: 湿滑道路低速/静止相关事件预期主要造成轻度至中度伤害。 | J20: E2 | K20: 依据本项目运行场景定义及概念阶段专家判断，OS11暴露度暂定为低概率；需由目标市场、车队或场景统计数据复核。 | L20: C2 | M20: 多数驾驶员可通过制动、转向或调整踏板控制后果，但需要及时反应。 | N20: =VLOOKUP(H20&J20&L20,'06_SEC准则'!$E$4:$I$39,5,FALSE) -> QM | O20: SG-002 | P20: 扭矩请求置0；请求无效；驾驶员声光告警 | Q20: 500 | R20: OPC-ITEM-DEF-001；运行场景分析；概念阶段专家判断待评审 | S20: =IF(N20="QM",0,IF(N20="A",1,IF(N20="B",2,IF(N20="C",3,IF(N20="D",4,""))))) -> 0 | T20: 待FuSa评审 | U20: TBD
A21: HE-018 | B21: Draft | C21: FUN-005/FUN-008 | D21: MF-002/MF-006/MF-012 | E21: H2 | F21: OS12 | G21: 车辆非预期减速，发生于OS12运行场景 | H21: S0 | I21: 该车辆状态下未识别可合理发生的伤害，待确认是否排除。 | J21: E0 | K21: 该场景与危害组合不适用或不可合理预见。 | L21: C0 | M21: 通常可控/不适用，需由评审确认。 | N21: ="QM" -> QM | O21: SG-002 | P21: 扭矩请求置0；请求无效；驾驶员声光告警 | Q21: 500 | R21: OPC-ITEM-DEF-001；运行场景分析；概念阶段专家判断待评审 | S21: =IF(N21="QM",0,IF(N21="A",1,IF(N21="B",2,IF(N21="C",3,IF(N21="D",4,""))))) -> 0 | T21: 待FuSa评审 | U21: TBD | V21: 该危害—场景组合暂按QM，排除理由需评审批准
A22: HE-019 | B22: Draft | C22: FUN-003/FUN-008 | D22: MF-003/MF-006 | E22: H3 | F22: OS1 | G22: 车辆加速不足，发生于OS1运行场景 | H22: S3 | I22: 高速公路发生车辆加速不足可能导致高速碰撞、行人碰撞或致命伤害。 | J22: E2 | K22: 依据本项目运行场景定义及概念阶段专家判断，OS1暴露度暂定为低概率；需由目标市场、车队或场景统计数据复核。 | L22: C2 | M22: 多数驾驶员可通过制动、转向或调整踏板控制后果，但需要及时反应。 | N22: =VLOOKUP(H22&J22&L22,'06_SEC准则'!$E$4:$I$39,5,FALSE) -> A | O22: SG-003 | P22: 告警并允许驾驶员采取替代操作；具体降级策略由FSC确定 | Q22: 500 | R22: OPC-ITEM-DEF-001；运行场景分析；概念阶段专家判断待评审 | S22: =IF(N22="QM",0,IF(N22="A",1,IF(N22="B",2,IF(N22="C",3,IF(N22="D",4,""))))) -> 1 | T22: 待FuSa评审 | U22: TBD
A23: HE-020 | B23: Draft | C23: FUN-003/FUN-008 | D23: MF-003/MF-006 | E23: H3 | F23: OS2 | G23: 车辆加速不足，发生于OS2运行场景 | H23: S2 | I23: 高速公路发生车辆加速不足可能导致严重碰撞或严重伤害，但存活概率较高。 | J23: E1 | K23: 依据本项目运行场景定义及概念阶段专家判断，OS2暴露度暂定为很低概率；需由目标市场、车队或场景统计数据复核。 | L23: C2 | M23: 多数驾驶员可通过制动、转向或调整踏板控制后果，但需要及时反应。 | N23: =VLOOKUP(H23&J23&L23,'06_SEC准则'!$E$4:$I$39,5,FALSE) -> QM | O23: SG-003 | P23: 告警并允许驾驶员采取替代操作；具体降级策略由FSC确定 | Q23: 500 | R23: OPC-ITEM-DEF-001；运行场景分析；概念阶段专家判断待评审 | S23: =IF(N23="QM",0,IF(N23="A",1,IF(N23="B",2,IF(N23="C",3,IF(N23="D",4,""))))) -> 0 | T23: 待FuSa评审 | U23: TBD
A24: HE-021 | B24: Draft | C24: FUN-003/FUN-008 | D24: MF-003/MF-006 | E24: H3 | F24: OS6 | G24: 车辆加速不足，发生于OS6运行场景 | H24: S2 | I24: 拥堵道路发生车辆加速不足可能导致严重碰撞或严重伤害，但存活概率较高。 | J24: E3 | K24: 依据本项目运行场景定义及概念阶段专家判断，OS6暴露度暂定为中等概率；需由目标市场、车队或场景统计数据复核。 | L24: C1 | M24: 驾驶员可通过独立制动或停止操作较容易地控制该情况。 | N24: =VLOOKUP(H24&J24&L24,'06_SEC准则'!$E$4:$I$39,5,FALSE) -> QM | O24: SG-003 | P24: 告警并允许驾驶员采取替代操作；具体降级策略由FSC确定 | Q24: 500 | R24: OPC-ITEM-DEF-001；运行场景分析；概念阶段专家判断待评审 | S24: =IF(N24="QM",0,IF(N24="A",1,IF(N24="B",2,IF(N24="C",3,IF(N24="D",4,""))))) -> 0 | T24: 待FuSa评审 | U24: TBD
A25: HE-022 | B25: Draft | C25: FUN-003/FUN-008 | D25: MF-003/MF-006 | E25: H3 | F25: OS7 | G25: 车辆加速不足，发生于OS7运行场景 | H25: S1 | I25: 拥堵道路低速/静止相关事件预期主要造成轻度至中度伤害。 | J25: E2 | K25: 依据本项目运行场景定义及概念阶段专家判断，OS7暴露度暂定为低概率；需由目标市场、车队或场景统计数据复核。 | L25: C1 | M25: 驾驶员可通过独立制动或停止操作较容易地控制该情况。 | N25: =VLOOKUP(H25&J25&L25,'06_SEC准则'!$E$4:$I$39,5,FALSE) -> QM | O25: SG-003 | P25: 告警并允许驾驶员采取替代操作；具体降级策略由FSC确定 | Q25: 500 | R25: OPC-ITEM-DEF-001；运行场景分析；概念阶段专家判断待评审 | S25: =IF(N25="QM",0,IF(N25="A",1,IF(N25="B",2,IF(N25="C",3,IF(N25="D",4,""))))) -> 0 | T25: 待FuSa评审 | U25: TBD
A26: HE-023 | B26: Draft | C26: FUN-003/FUN-008 | D26: MF-003/MF-006 | E26: H3 | F26: OS8 | G26: 车辆加速不足，发生于OS8运行场景 | H26: S1 | I26: 拥堵道路低速/静止相关事件预期主要造成轻度至中度伤害。 | J26: E2 | K26: 依据本项目运行场景定义及概念阶段专家判断，OS8暴露度暂定为低概率；需由目标市场、车队或场景统计数据复核。 | L26: C1 | M26: 驾驶员可通过独立制动或停止操作较容易地控制该情况。 | N26: =VLOOKUP(H26&J26&L26,'06_SEC准则'!$E$4:$I$39,5,FALSE) -> QM | O26: SG-003 | P26: 告警并允许驾驶员采取替代操作；具体降级策略由FSC确定 | Q26: 500 | R26: OPC-ITEM-DEF-001；运行场景分析；概念阶段专家判断待评审 | S26: =IF(N26="QM",0,IF(N26="A",1,IF(N26="B",2,IF(N26="C",3,IF(N26="D",4,""))))) -> 0 | T26: 待FuSa评审 | U26: TBD
A27: HE-024 | B27: Draft | C27: FUN-003/FUN-008 | D27: MF-003/MF-006 | E27: H3 | F27: OS9 | G27: 车辆加速不足，发生于OS9运行场景 | H27: S2 | I27: 湿滑道路发生车辆加速不足可能导致严重碰撞或严重伤害，但存活概率较高。 | J27: E1 | K27: 依据本项目运行场景定义及概念阶段专家判断，OS9暴露度暂定为很低概率；需由目标市场、车队或场景统计数据复核。 | L27: C2 | M27: 多数驾驶员可通过制动、转向或调整踏板控制后果，但需要及时反应。 | N27: =VLOOKUP(H27&J27&L27,'06_SEC准则'!$E$4:$I$39,5,FALSE) -> QM | O27: SG-003 | P27: 告警并允许驾驶员采取替代操作；具体降级策略由FSC确定 | Q27: 500 | R27: OPC-ITEM-DEF-001；运行场景分析；概念阶段专家判断待评审 | S27: =IF(N27="QM",0,IF(N27="A",1,IF(N27="B",2,IF(N27="C",3,IF(N27="D",4,""))))) -> 0 | T27: 待FuSa评审 | U27: TBD
A28: HE-025 | B28: Draft | C28: FUN-003/FUN-008 | D28: MF-003/MF-006 | E28: H3 | F28: OS10 | G28: 车辆加速不足，发生于OS10运行场景 | H28: S1 | I28: 湿滑道路低速/静止相关事件预期主要造成轻度至中度伤害。 | J28: E2 | K28: 依据本项目运行场景定义及概念阶段专家判断，OS10暴露度暂定为低概率；需由目标市场、车队或场景统计数据复核。 | L28: C1 | M28: 驾驶员可通过独立制动或停止操作较容易地控制该情况。 | N28: =VLOOKUP(H28&J28&L28,'06_SEC准则'!$E$4:$I$39,5,FALSE) -> QM | O28: SG-003 | P28: 告警并允许驾驶员采取替代操作；具体降级策略由FSC确定 | Q28: 500 | R28: OPC-ITEM-DEF-001；运行场景分析；概念阶段专家判断待评审 | S28: =IF(N28="QM",0,IF(N28="A",1,IF(N28="B",2,IF(N28="C",3,IF(N28="D",4,""))))) -> 0 | T28: 待FuSa评审 | U28: TBD
A29: HE-026 | B29: Draft | C29: FUN-003/FUN-008 | D29: MF-003/MF-006 | E29: H3 | F29: OS11 | G29: 车辆加速不足，发生于OS11运行场景 | H29: S1 | I29: 湿滑道路低速/静止相关事件预期主要造成轻度至中度伤害。 | J29: E2 | K29: 依据本项目运行场景定义及概念阶段专家判断，OS11暴露度暂定为低概率；需由目标市场、车队或场景统计数据复核。 | L29: C1 | M29: 驾驶员可通过独立制动或停止操作较容易地控制该情况。 | N29: =VLOOKUP(H29&J29&L29,'06_SEC准则'!$E$4:$I$39,5,FALSE) -> QM | O29: SG-003 | P29: 告警并允许驾驶员采取替代操作；具体降级策略由FSC确定 | Q29: 500 | R29: OPC-ITEM-DEF-001；运行场景分析；概念阶段专家判断待评审 | S29: =IF(N29="QM",0,IF(N29="A",1,IF(N29="B",2,IF(N29="C",3,IF(N29="D",4,""))))) -> 0 | T29: 待FuSa评审 | U29: TBD
A30: HE-027 | B30: Draft | C30: FUN-003/FUN-008 | D30: MF-003/MF-006 | E30: H3 | F30: OS12 | G30: 车辆加速不足，发生于OS12运行场景 | H30: S1 | I30: 湿滑道路低速/静止相关事件预期主要造成轻度至中度伤害。 | J30: E1 | K30: 依据本项目运行场景定义及概念阶段专家判断，OS12暴露度暂定为很低概率；需由目标市场、车队或场景统计数据复核。 | L30: C2 | M30: 多数驾驶员可通过制动、转向或调整踏板控制后果，但需要及时反应。 | N30: =VLOOKUP(H30&J30&L30,'06_SEC准则'!$E$4:$I$39,5,FALSE) -> QM | O30: SG-003 | P30: 告警并允许驾驶员采取替代操作；具体降级策略由FSC确定 | Q30: 500 | R30: OPC-ITEM-DEF-001；运行场景分析；概念阶段专家判断待评审 | S30: =IF(N30="QM",0,IF(N30="A",1,IF(N30="B",2,IF(N30="C",3,IF(N30="D",4,""))))) -> 0 | T30: 待FuSa评审 | U30: TBD
A31: HE-028 | B31: Draft | C31: FUN-005/FUN-008 | D31: MF-004/MF-006 | E31: H4 | F31: OS1 | G31: 车辆减速不足，发生于OS1运行场景 | H31: S3 | I31: 高速公路发生车辆减速不足可能导致高速碰撞、行人碰撞或致命伤害。 | J31: E2 | K31: 依据本项目运行场景定义及概念阶段专家判断，OS1暴露度暂定为低概率；需由目标市场、车队或场景统计数据复核。 | L31: C2 | M31: 多数驾驶员可通过制动、转向或调整踏板控制后果，但需要及时反应。 | N31: =VLOOKUP(H31&J31&L31,'06_SEC准则'!$E$4:$I$39,5,FALSE) -> A | O31: SG-004 | P31: 告警并提示使用独立液压制动；具体安全状态由FSC确认 | Q31: 500 | R31: OPC-ITEM-DEF-001；运行场景分析；概念阶段专家判断待评审 | S31: =IF(N31="QM",0,IF(N31="A",1,IF(N31="B",2,IF(N31="C",3,IF(N31="D",4,""))))) -> 1 | T31: 待FuSa评审 | U31: TBD
A32: HE-029 | B32: Draft | C32: FUN-005/FUN-008 | D32: MF-004/MF-006 | E32: H4 | F32: OS2 | G32: 车辆减速不足，发生于OS2运行场景 | H32: S3 | I32: 高速公路发生车辆减速不足可能导致高速碰撞、行人碰撞或致命伤害。 | J32: E2 | K32: 依据本项目运行场景定义及概念阶段专家判断，OS2暴露度暂定为低概率；需由目标市场、车队或场景统计数据复核。 | L32: C2 | M32: 多数驾驶员可通过制动、转向或调整踏板控制后果，但需要及时反应。 | N32: =VLOOKUP(H32&J32&L32,'06_SEC准则'!$E$4:$I$39,5,FALSE) -> A | O32: SG-004 | P32: 告警并提示使用独立液压制动；具体安全状态由FSC确认 | Q32: 500 | R32: OPC-ITEM-DEF-001；运行场景分析；概念阶段专家判断待评审 | S32: =IF(N32="QM",0,IF(N32="A",1,IF(N32="B",2,IF(N32="C",3,IF(N32="D",4,""))))) -> 1 | T32: 待FuSa评审 | U32: TBD
A33: HE-030 | B33: Draft | C33: FUN-005/FUN-008 | D33: MF-004/MF-006 | E33: H4 | F33: OS6 | G33: 车辆减速不足，发生于OS6运行场景 | H33: S3 | I33: 拥堵道路发生车辆减速不足可能导致高速碰撞、行人碰撞或致命伤害。 | J33: E3 | K33: 依据本项目运行场景定义及概念阶段专家判断，OS6暴露度暂定为中等概率；需由目标市场、车队或场景统计数据复核。 | L33: C1 | M33: 驾驶员可通过独立制动或停止操作较容易地控制该情况。 | N33: =VLOOKUP(H33&J33&L33,'06_SEC准则'!$E$4:$I$39,5,FALSE) -> A | O33: SG-004 | P33: 告警并提示使用独立液压制动；具体安全状态由FSC确认 | Q33: 500 | R33: OPC-ITEM-DEF-001；运行场景分析；概念阶段专家判断待评审 | S33: =IF(N33="QM",0,IF(N33="A",1,IF(N33="B",2,IF(N33="C",3,IF(N33="D",4,""))))) -> 1 | T33: 待FuSa评审 | U33: TBD
... A38: HE-035 | B38: Draft | C38: FUN-005/FUN-008 | D38: MF-004/MF-006 | E38: H4 | F38: OS11 | G38: 车辆减速不足，发生于OS11运行场景 | H38: S1 | I38: 湿滑道路低速/静止相关事件预期主要造成轻度至中度伤害。 | J38: E2 | K38: 依据本项目运行场景定义及概念阶段专家判断，OS11暴露度暂定为低概率；需由目标市场、车队或场景统计数据复核。 | L38: C1 | M38: 驾驶员可通过独立制动或停止操作较容易地控制该情况。 | N38: =VLOOKUP(H38&J38&L38,'06_SEC准则'!$E$4:$I$39,5,FALSE) -> QM | O38: SG-004 | P38: 告警并提示使用独立液压制动；具体安全状态由FSC确认 | Q38: 500 | R38: OPC-ITEM-DEF-001；运行场景分析；概念阶段专家判断待评审 | S38: =IF(N38="QM",0,IF(N38="A",1,IF(N38="B",2,IF(N38="C",3,IF(N38="D",4,""))))) -> 0 | T38: 待FuSa评审 | U38: TBD
A39: HE-036 | B39: Draft | C39: FUN-005/FUN-008 | D39: MF-004/MF-006 | E39: H4 | F39: OS12 | G39: 车辆减速不足，发生于OS12运行场景 | H39: S0 | I39: 该车辆状态下未识别可合理发生的伤害，待确认是否排除。 | J39: E0 | K39: 该场景与危害组合不适用或不可合理预见。 | L39: C0 | M39: 通常可控/不适用，需由评审确认。 | N39: ="QM" -> QM | O39: SG-004 | P39: 告警并提示使用独立液压制动；具体安全状态由FSC确认 | Q39: 500 | R39: OPC-ITEM-DEF-001；运行场景分析；概念阶段专家判断待评审 | S39: =IF(N39="QM",0,IF(N39="A",1,IF(N39="B",2,IF(N39="C",3,IF(N39="D",4,""))))) -> 0 | T39: 待FuSa评审 | U39: TBD | V39: 该危害—场景组合暂按QM，排除理由需评审批准
A40: HE-037 | B40: Draft | C40: FUN-002/FUN-005/FUN-006 | D40: MF-007/MF-008/MF-011/MF-012 | E40: H5 | F40: OS1 | G40: 车辆向错误方向运动，发生于OS1运行场景 | H40: S3 | I40: 高速公路发生车辆向错误方向运动可能导致高速碰撞、行人碰撞或致命伤害。 | J40: E2 | K40: 依据本项目运行场景定义及概念阶段专家判断，OS1暴露度暂定为低概率；需由目标市场、车队或场景统计数据复核。 | L40: C3 | M40: 车辆向错误方向运动发生后驾驶员可用反应时间或外部措施有限，难以控制或不可控。 | N40: =VLOOKUP(H40&J40&L40,'06_SEC准则'!$E$4:$I$39,5,FALSE) -> B | O40: SG-005 | P40: 禁止危险方向扭矩；限制/置0扭矩；驾驶员告警 | Q40: 200 | R40: OPC-ITEM-DEF-001；运行场景分析；概念阶段专家判断待评审 | S40: =IF(N40="QM",0,IF(N40="A",1,IF(N40="B",2,IF(N40="C",3,IF(N40="D",4,""))))) -> 2 | T40: 待FuSa评审 | U40: TBD
A41: HE-038 | B41: Draft | C41: FUN-002/FUN-005/FUN-006 | D41: MF-007/MF-008/MF-011/MF-012 | E41: H5 | F41: OS2 | G41: 车辆向错误方向运动，发生于OS2运行场景 | H41: S3 | I41: 高速公路发生车辆向错误方向运动可能导致高速碰撞、行人碰撞或致命伤害。 | J41: E1 | K41: 依据本项目运行场景定义及概念阶段专家判断，OS2暴露度暂定为很低概率；需由目标市场、车队或场景统计数据复核。 | L41: C3 | M41: 车辆向错误方向运动发生后驾驶员可用反应时间或外部措施有限，难以控制或不可控。 | N41: =VLOOKUP(H41&J41&L41,'06_SEC准则'!$E$4:$I$39,5,FALSE) -> A | O41: SG-005 | P41: 禁止危险方向扭矩；限制/置0扭矩；驾驶员告警 | Q41: 200 | R41: OPC-ITEM-DEF-001；运行场景分析；概念阶段专家判断待评审 | S41: =IF(N41="QM",0,IF(N41="A",1,IF(N41="B",2,IF(N41="C",3,IF(N41="D",4,""))))) -> 1 | T41: 待FuSa评审 | U41: TBD
A42: HE-039 | B42: Draft | C42: FUN-002/FUN-005/FUN-006 | D42: MF-007/MF-008/MF-011/MF-012 | E42: H5 | F42: OS6 | G42: 车辆向错误方向运动，发生于OS6运行场景 | H42: S2 | I42: 拥堵道路发生车辆向错误方向运动可能导致严重碰撞或严重伤害，但存活概率较高。 | J42: E3 | K42: 依据本项目运行场景定义及概念阶段专家判断，OS6暴露度暂定为中等概率；需由目标市场、车队或场景统计数据复核。 | L42: C3 | M42: 车辆向错误方向运动发生后驾驶员可用反应时间或外部措施有限，难以控制或不可控。 | N42: =VLOOKUP(H42&J42&L42,'06_SEC准则'!$E$4:$I$39,5,FALSE) -> B | O42: SG-005 | P42: 禁止危险方向扭矩；限制/置0扭矩；驾驶员告警 | Q42: 200 | R42: OPC-ITEM-DEF-001；运行场景分析；概念阶段专家判断待评审 | S42: =IF(N42="QM",0,IF(N42="A",1,IF(N42="B",2,IF(N42="C",3,IF(N42="D",4,""))))) -> 2 | T42: 待FuSa评审 | U42: TBD
A43: HE-040 | B43: Draft | C43: FUN-002/FUN-005/FUN-006 | D43: MF-007/MF-008/MF-011/MF-012 | E43: H5 | F43: OS7 | G43: 车辆向错误方向运动，发生于OS7运行场景 | H43: S2 | I43: 拥堵道路发生车辆向错误方向运动可能导致严重碰撞或严重伤害，但存活概率较高。 | J43: E2 | K43: 依据本项目运行场景定义及概念阶段专家判断，OS7暴露度暂定为低概率；需由目标市场、车队或场景统计数据复核。 | L43: C3 | M43: 车辆向错误方向运动发生后驾驶员可用反应时间或外部措施有限，难以控制或不可控。 | N43: =VLOOKUP(H43&J43&L43,'06_SEC准则'!$E$4:$I$39,5,FALSE) -> A | O43: SG-005 | P43: 禁止危险方向扭矩；限制/置0扭矩；驾驶员告警 | Q43: 200 | R43: OPC-ITEM-DEF-001；运行场景分析；概念阶段专家判断待评审 | S43: =IF(N43="QM",0,IF(N43="A",1,IF(N43="B",2,IF(N43="C",3,IF(N43="D",4,""))))) -> 1 | T43: 待FuSa评审 | U43: TBD
A44: HE-041 | B44: Draft | C44: FUN-002/FUN-005/FUN-006 | D44: MF-007/MF-008/MF-011/MF-012 | E44: H5 | F44: OS8 | G44: 车辆向错误方向运动，发生于OS8运行场景 | H44: S2 | I44: 拥堵道路发生车辆向错误方向运动可能导致严重碰撞或严重伤害，但存活概率较高。 | J44: E3 | K44: 依据本项目运行场景定义及概念阶段专家判断，OS8暴露度暂定为中等概率；需由目标市场、车队或场景统计数据复核。 | L44: C3 | M44: 车辆向错误方向运动发生后驾驶员可用反应时间或外部措施有限，难以控制或不可控。 | N44: =VLOOKUP(H44&J44&L44,'06_SEC准则'!$E$4:$I$39,5,FALSE) -> B | O44: SG-005 | P44: 禁止危险方向扭矩；限制/置0扭矩；驾驶员告警 | Q44: 200 | R44: OPC-ITEM-DEF-001；运行场景分析；概念阶段专家判断待评审 | S44: =IF(N44="QM",0,IF(N44="A",1,IF(N44="B",2,IF(N44="C",3,IF(N44="D",4,""))))) -> 2 | T44: 待FuSa评审 | U44: TBD
...

Sheet 05_安全目标
A1: 安全目标与HARA结论
A2: SG-001～SG-005由车辆级危害及危险事件直接导出；SG-006作为跨安全目标的检测与反应约束，后续在FSC中分解为FSR。
A3: 安全目标ID | B3: 安全目标 | C3: 关联危害 | D3: 计算最高ASIL分值 | E3: 计算ASIL | F3: 评审基线ASIL | G3: 内部一致性 | H3: 安全状态 | I3: FTTI(ms) | J3: 运行场景范围 | K3: 验证方法建议 | L3: 状态 | M3: 编制 | N3: 备注
A4: SG-001 | B4: 防止车辆非预期加速 | C4: H1 | D4: =_xludf.MAXIFS('04_危害事件'!$S$4:$S$48,'04_危害事件'!$O$4:$O$48,A4) -> #NAME? | E4: =CHOOSE(D4+1,"QM","A","B","C","D") -> #NAME? | F4: C | G4: =IF(E4=F4,"一致","需复核") -> #NAME? | H4: 扭矩请求置0并撤销有效性；声光告警 | I4: 100 | J4: 所有适用运行场景 | K4: 故障注入、FTTI、扭矩监控 | L4: Draft | M4: Nan
A5: SG-002 | B5: 防止车辆非预期减速 | C5: H2 | D5: =_xludf.MAXIFS('04_危害事件'!$S$4:$S$48,'04_危害事件'!$O$4:$O$48,A5) -> #NAME? | E5: =CHOOSE(D5+1,"QM","A","B","C","D") -> #NAME? | F5: A | G5: =IF(E5=F5,"一致","需复核") -> #NAME? | H5: 扭矩请求置0并撤销有效性；声光告警 | I5: 500 | J5: 所有适用运行场景 | K5: 故障注入、FTTI、扭矩监控 | L5: Draft | M5: Nan
A6: SG-003 | B6: 防止车辆加速不足 | C6: H3 | D6: =_xludf.MAXIFS('04_危害事件'!$S$4:$S$48,'04_危害事件'!$O$4:$O$48,A6) -> #NAME? | E6: =CHOOSE(D6+1,"QM","A","B","C","D") -> #NAME? | F6: A | G6: =IF(E6=F6,"一致","需复核") -> #NAME? | H6: 告警；降级/安全状态由FSC定义 | I6: 500 | J6: 高速合流、超车和交通流场景 | K6: 故障注入、性能与告警验证 | L6: Draft | M6: Nan | N6: 安全状态需评审
A7: SG-004 | B7: 防止车辆减速不足 | C7: H4 | D7: =_xludf.MAXIFS('04_危害事件'!$S$4:$S$48,'04_危害事件'!$O$4:$O$48,A7) -> #NAME? | E7: =CHOOSE(D7+1,"QM","A","B","C","D") -> #NAME? | F7: A | G7: =IF(E7=F7,"一致","需复核") -> #NAME? | H7: 告警并提示使用独立液压制动；FSC确认 | I7: 500 | J7: 单踏板制动适用场景 | K7: 故障注入、驾驶员告警、外部措施验证 | L7: Draft | M7: Nan | N7: 安全状态需评审
A8: SG-005 | B8: 防止车辆向错误方向运动 | C8: H5 | D8: =_xludf.MAXIFS('04_危害事件'!$S$4:$S$48,'04_危害事件'!$O$4:$O$48,A8) -> #NAME? | E8: =CHOOSE(D8+1,"QM","A","B","C","D") -> #NAME? | F8: B | G8: =IF(E8=F8,"一致","需复核") -> #NAME? | H8: 禁止危险方向扭矩；限制或置0扭矩；告警 | I8: 200 | J8: 换挡、倒车、零速和坡道场景 | K8: 方向互锁、故障注入、FTTI | L8: Draft | M8: Nan
A9: SG-006 | B9: 在相关FTTI内检测故障并完成规定的安全反应 | C9: H1-H5 | D9: =MAX(D4:D8) -> #NAME? | E9: =CHOOSE(D9+1,"QM","A","B","C","D") -> #NAME? | F9: C | G9: =IF(E9=F9,"一致","需复核") -> #NAME? | H9: 由SG-001～SG-005分别定义安全反应 | I9: 100 | J9: 所有适用运行场景 | K9: FTTI预算、故障注入、反应时间测试 | L9: Draft | M9: Nan | N9: 跨安全目标约束；在FSC中分解

Sheet 07_追踪矩阵
A1: HARA 双向追踪矩阵
A2: 从Item功能与功能异常追踪至危害、危险事件、安全目标和后续FSC输入。
A3: 追踪ID | B3: 功能ID | C3: 功能异常ID | D3: 危害ID | E3: 危险事件范围 | F3: 安全目标ID | G3: ASIL | H3: 安全状态/措施 | I3: 后续工作产品 | J3: 状态
A4: TR-001 | B4: FUN-003/FUN-005/FUN-008 | C4: MF-001/MF-005/MF-009/MF-012 | D4: H1 | E4: HE-001～HE-009 | F4: SG-001 | G4: C | H4: 零扭矩/无效请求/告警 | I4: FSC/FSR/FTA/测试 | J4: Draft
A5: TR-002 | B5: FUN-005/FUN-008 | C5: MF-002/MF-006/MF-012 | D5: H2 | E5: HE-010～HE-018 | F5: SG-002 | G5: A | H5: 零扭矩/无效请求/告警 | I5: FSC/FSR/测试 | J5: Draft
A6: TR-003 | B6: FUN-003/FUN-008 | C6: MF-003/MF-006 | D6: H3 | E6: HE-019～HE-027 | F6: SG-003 | G6: A | H6: 告警/降级策略待FSC | I6: FSC/FSR/测试 | J6: Draft
A7: TR-004 | B7: FUN-005/FUN-008 | C7: MF-004/MF-006 | D7: H4 | E7: HE-028～HE-036 | F7: SG-004 | G7: A | H7: 告警/外部制动/策略待FSC | I7: FSC/FSR/DFA/测试 | J7: Draft
A8: TR-005 | B8: FUN-002/FUN-005/FUN-006 | C8: MF-007/MF-008/MF-011/MF-012 | D8: H5 | E8: HE-037～HE-045 | F8: SG-005 | G8: B | H8: 禁止危险方向扭矩/限扭/告警 | I8: FSC/FSR/FTA/测试 | J8: Draft
A9: TR-006 | B9: FUN-009/FUN-010 | C9: MF-010 | D9: H1-H5 | E9: 全部相关危险事件 | F9: SG-006 | G9: C | H9: 在相关FTTI内检测并完成安全反应 | I9: FTTI预算/FSR/测试 | J9: Draft

Sheet 08_开放问题
A1: 开放问题与评审行动项
A2: 所有Open问题必须在HARA基线批准前关闭，或形成经批准的偏差/假设。
A3: 问题ID | B3: 类别 | C3: 问题描述 | D3: 影响对象 | E3: 建议措施 | F3: 责任人 | G3: 状态 | H3: 目标日期 | I3: 关闭证据 | J3: 备注
A4: OI-001 | B4: 安全目标分解 | C4: SG-006是跨安全目标的检测与反应约束，需要在FSC中分解至SG-001～SG-005对应FSR。 | D4: SG-006 | E4: 建立检测、确认和安全反应时间预算，并双向链接各FSR。 | F4: Nan | G4: Open
A5: OI-002 | B5: 场景完整性 | C5: HARA基线覆盖9个设计运行场景；城市普通道路、坡道、初始化/恢复和危险换挡已登记但尚未进入基线评估。 | D5: OS13～OS16 | E5: 确认扩展场景适用性，批准后补充危险事件及S/E/C评估。 | F5: Nan | G5: Open
A6: OI-003 | B6: 证据 | C6: 绝大多数E和C评级仅有专家判断，缺少车队、事故或驾驶员研究数据。 | D6: 全部HE | E6: 收集客观数据并组织跨职能专家评审。 | F6: Nan | G6: Open
A7: OI-004 | B7: 外部措施 | C7: 液压制动与Item的独立性尚未通过DFA确认。 | D7: SG-003/SG-004 | E7: 执行DFA并建立外部措施需求。 | F7: Nan | G7: Open
A8: OI-005 | B8: FTTI | C8: 100/200/500 ms缺少车辆动力学和伤害演化依据。 | D8: SG-001～SG-005 | E8: 建立FTTI分析和检测/反应时间预算。 | F8: Nan | G8: Open
A9: OI-006 | B9: 安全状态 | C9: SG-003和SG-004目前主要采用告警，是否足以降低风险尚未确认。 | D9: SG-003/SG-004 | E9: 在FSC中定义可验证的降级或安全状态。 | F9: Nan | G9: Open
A10: OI-007 | B10: 危险识别复核 | C10: MF-001～MF-012已纳入危害映射，仍需使用HAZOP/STPA/FMEA执行独立完整性复核。 | D10: 全部MF/HE | E10: 组织跨职能评审并记录未识别新危害的客观证据。 | F10: Nan | G10: Open
A11: OI-008 | B11: 参数边界 | C11: −80/+80 Nm、5 km/h、0.2 km/h、10%坡度等需确认车辆级依据。 | D11: Item约束 | E11: 记录标定来源和车辆级批准。 | F11: Nan | G11: Open

Sheet 09_变更记录
A1: HARA 变更记录
A2: 每次受控修改应记录变更原因、影响对象、评审结论和关联变更请求。
A3: 版本 | B3: 日期 | C3: 变更请求ID | D3: 变更内容 | E3: 影响对象 | F3: 影响分析 | G3: 编制人 | H3: 评审/批准 | I3: 状态
A4: 1.0 | B4: 2026-08-06 | C4: N/A | D4: 建立单踏板控制系统HARA初始基线，包含Item范围、功能异常、运行场景、危险事件、ASIL、安全目标和追踪关系。 | E4: 全部工作表 | F4: 首次建立项目HARA工作产品；待授权功能安全团队评审批准。 | G4: Nan | H4: Yi | I4: Draft
